Workbook
Name Slicer_Age_Group: #N/A
Name Slicer_Family_Group: #N/A
Name Slicer_Fare_Category: #N/A
Name Slicer_Passenger_Class: #N/A
Name Slicer_Sex: #N/A

Sheet RawData
A1: PassengerId | B1: Survived | C1: Pclass | D1: Name | E1: Sex | F1: Age | G1: SibSp | H1: Parch | I1: Ticket | J1: Fare
A2: 1 | B2: 0 | C2: 3 | D2: Braund, Mr. Owen Harris | E2: male | F2: 22 | G2: 1 | H2: 0 | I2: A/5 21171 | J2: 7.25
A3: 2 | B3: 1 | C3: 1 | D3: Cumings, Mrs. John Bradley (Florence Briggs Thayer) | E3: female | F3: 38 | G3: 1 | H3: 0 | I3: PC 17599 | J3: 71.2833
A4: 3 | B4: 1 | C4: 3 | D4: Heikkinen, Miss. Laina | E4: female | F4: 26 | G4: 0 | H4: 0 | I4: STON/O2. 3101282 | J4: 7.925
A5: 4 | B5: 1 | C5: 1 | D5: Futrelle, Mrs. Jacques Heath (Lily May Peel) | E5: female | F5: 35 | G5: 1 | H5: 0 | I5: 113803 | J5: 53.1
A6: 5 | B6: 0 | C6: 3 | D6: Allen, Mr. William Henry | E6: male | F6: 35 | G6: 0 | H6: 0 | I6: 373450 | J6: 8.05
A7: 6 | B7: 0 | C7: 3 | D7: Moran, Mr. James | E7: male | G7: 0 | H7: 0 | I7: 330877 | J7: 8.4583
A8: 7 | B8: 0 | C8: 1 | D8: McCarthy, Mr. Timothy J | E8: male | F8: 54 | G8: 0 | H8: 0 | I8: 17463 | J8: 51.8625
A9: 8 | B9: 0 | C9: 3 | D9: Palsson, Master. Gosta Leonard | E9: male | F9: 2 | G9: 3 | H9: 1 | I9: 349909 | J9: 21.075
A10: 9 | B10: 1 | C10: 3 | D10: Johnson, Mrs. Oscar W (Elisabeth Vilhelmina Berg) | E10: female | F10: 27 | G10: 0 | H10: 2 | I10: 347742 | J10: 11.1333
A11: 10 | B11: 1 | C11: 2 | D11: Nasser, Mrs. Nicholas (Adele Achem) | E11: female | F11: 14 | G11: 1 | H11: 0 | I11: 237736 | J11: 30.0708
A12: 11 | B12: 1 | C12: 3 | D12: Sandstrom, Miss. Marguerite Rut | E12: female | F12: 4 | G12: 1 | H12: 1 | I12: PP 9549 | J12: 16.7
A13: 12 | B13: 1 | C13: 1 | D13: Bonnell, Miss. Elizabeth | E13: female | F13: 58 | G13: 0 | H13: 0 | I13: 113783 | J13: 26.55
A14: 13 | B14: 0 | C14: 3 | D14: Saundercock, Mr. William Henry | E14: male | F14: 20 | G14: 0 | H14: 0 | I14: A/5. 2151 | J14: 8.05
A15: 14 | B15: 0 | C15: 3 | D15: Andersson, Mr. Anders Johan | E15: male | F15: 39 | G15: 1 | H15: 5 | I15: 347082 | J15: 31.275
A16: 15 | B16: 0 | C16: 3 | D16: Vestrom, Miss. Hulda Amanda Adolfina | E16: female | F16: 14 | G16: 0 | H16: 0 | I16: 350406 | J16: 7.8542
A17: 16 | B17: 1 | C17: 2 | D17: Hewlett, Mrs. (Mary D Kingcome) | E17: female | F17: 55 | G17: 0 | H17: 0 | I17: 248706 | J17: 16
A18: 17 | B18: 0 | C18: 3 | D18: Rice, Master. Eugene | E18: male | F18: 2 | G18: 4 | H18: 1 | I18: 382652 | J18: 29.125
A19: 18 | B19: 1 | C19: 2 | D19: Williams, Mr. Charles Eugene | E19: male | G19: 0 | H19: 0 | I19: 244373 | J19: 13
A20: 19 | B20: 0 | C20: 3 | D20: Vander Planke, Mrs. Julius (Emelia Maria Vandemoortele) | E20: female | F20: 31 | G20: 1 | H20: 0 | I20: 345763 | J20: 18
A21: 20 | B21: 1 | C21: 3 | D21: Masselmani, Mrs. Fatima | E21: female | G21: 0 | H21: 0 | I21: 2649 | J21: 7.225
A22: 21 | B22: 0 | C22: 2 | D22: Fynney, Mr. Joseph J | E22: male | F22: 35 | G22: 0 | H22: 0 | I22: 239865 | J22: 26
A23: 22 | B23: 1 | C23: 2 | D23: Beesley, Mr. Lawrence | E23: male | F23: 34 | G23: 0 | H23: 0 | I23: 248698 | J23: 13
A24: 23 | B24: 1 | C24: 3 | D24: McGowan, Miss. Anna "Annie" | E24: female | F24: 15 | G24: 0 | H24: 0 | I24: 330923 | J24: 8.0292
A25: 24 | B25: 1 | C25: 1 | D25: Sloper, Mr. William Thompson | E25: male | F25: 28 | G25: 0 | H25: 0 | I25: 113788 | J25: 35.5
A26: 25 | B26: 0 | C26: 3 | D26: Palsson, Miss. Torborg Danira | E26: female | F26: 8 | G26: 3 | H26: 1 | I26: 349909 | J26: 21.075
A27: 26 | B27: 1 | C27: 3 | D27: Asplund, Mrs. Carl Oscar (Selma Augusta Emilia Johansson) | E27: female | F27: 38 | G27: 1 | H27: 5 | I27: 347077 | J27: 31.3875
A28: 27 | B28: 0 | C28: 3 | D28: Emir, Mr. Farred Chehab | E28: male | G28: 0 | H28: 0 | I28: 2631 | J28: 7.225
A29: 28 | B29: 0 | C29: 1 | D29: Fortune, Mr. Charles Alexander | E29: male | F29: 19 | G29: 3 | H29: 2 | I29: 19950 | J29: 263
A30: 29 | B30: 1 | C30: 3 | D30: O'Dwyer, Miss. Ellen "Nellie" | E30: female | G30: 0 | H30: 0 | I30: 330959 | J30: 7.8792
A31: 30 | B31: 0 | C31: 3 | D31: Todoroff, Mr. Lalio | E31: male | G31: 0 | H31: 0 | I31: 349216 | J31: 7.8958
A32: 31 | B32: 0 | C32: 1 | D32: Uruchurtu, Don. Manuel E | E32: male | F32: 40 | G32: 0 | H32: 0 | I32: PC 17601 | J32: 27.7208
A33: 32 | B33: 1 | C33: 1 | D33: Spencer, Mrs. William Augustus (Marie Eugenie) | E33: female | G33: 1 | H33: 0 | I33: PC 17569 | J33: 146.5208
A34: 33 | B34: 1 | C34: 3 | D34: Glynn, Miss. Mary Agatha | E34: female | G34: 0 | H34: 0 | I34: 335677 | J34: 7.75
A35: 34 | B35: 0 | C35: 2 | D35: Wheadon, Mr. Edward H | E35: male | F35: 66 | G35: 0 | H35: 0 | I35: C.A. 24579 | J35: 10.5
A36: 35 | B36: 0 | C36: 1 | D36: Meyer, Mr. Edgar Joseph | E36: male | F36: 28 | G36: 1 | H36: 0 | I36: PC 17604 | J36: 82.1708
A37: 36 | B37: 0 | C37: 1 | D37: Holverson, Mr. Alexander Oskar | E37: male | F37: 42 | G37: 1 | H37: 0 | I37: 113789 | J37: 52
A38: 37 | B38: 1 | C38: 3 | D38: Mamee, Mr. Hanna | E38: male | G38: 0 | H38: 0 | I38: 2677 | J38: 7.2292
A39: 38 | B39: 0 | C39: 3 | D39: Cann, Mr. Ernest Charles | E39: male | F39: 21 | G39: 0 | H39: 0 | I39: A./5. 2152 | J39: 8.05
A40: 39 | B40: 0 | C40: 3 | D40: Vander Planke, Miss. Augusta Maria | E40: female | F40: 18 | G40: 2 | H40: 0 | I40: 345764 | J40: 18
...

Sheet CleanedData
A1: PassengerId | B1: Survived | C1: Pclass | D1: Name | E1: Sex | F1: Age | G1: SibSp | H1: Parch | I1: Ticket | J1: Fare | K1: Survival Status | L1: Age Group | M1: Family Size | N1: Family Group | O1: Fare Category | P1: Passenger Class | Q1: Gender Code
A2: 1 | B2: 0 | C2: 3 | D2: Braund, Mr. Owen Harris | E2: male | F2: 22 | G2: 1 | H2: 0 | I2: A/5 21171 | J2: 7.25 | K2: =IF(B2=1, "Survived", "Died") -> Died | L2: =IF(F2<18, "Child", IF(F2<35, "Young Adult", IF(F2<60, "Adult", "Senior"))) -> Young Adult | M2: =G2+H2+1 -> 2 | N2: =IF(M2=1,"Alone",IF(M2<=4,"Small Family","Large Family")) -> Small Family | O2: =IF(J2<25, "Low Fare", IF(J2<=100, "Medium Fare", "High Fare")) -> Low Fare | P2: =IF(C2=1, "First Class", IF(C2=2, "Second Class", "Third Class")) -> Third Class | Q2: =IF(E2="male", 1, 2) -> 1
A3: 2 | B3: 1 | C3: 1 | D3: Cumings, Mrs. John Bradley (Florence Briggs Thayer) | E3: female | F3: 38 | G3: 1 | H3: 0 | I3: PC 17599 | J3: 71.2833 | K3: =IF(B3=1, "Survived", "Died") -> Survived | L3: =IF(F3<18, "Child", IF(F3<35, "Young Adult", IF(F3<60, "Adult", "Senior"))) -> Adult | M3: =G3+H3+1 -> 2 | N3: =IF(M3=1,"Alone",IF(M3<=4,"Small Family","Large Family")) -> Small Family | O3: =IF(J3<25, "Low Fare", IF(J3<=100, "Medium Fare", "High Fare")) -> Medium Fare | P3: =IF(C3=1, "First Class", IF(C3=2, "Second Class", "Third Class")) -> First Class | Q3: =IF(E3="male", 1, 2) -> 2
A4: 3 | B4: 1 | C4: 3 | D4: Heikkinen, Miss. Laina | E4: female | F4: 26 | G4: 0 | H4: 0 | I4: STON/O2. 3101282 | J4: 7.925 | K4: =IF(B4=1, "Survived", "Died") -> Survived | L4: =IF(F4<18, "Child", IF(F4<35, "Young Adult", IF(F4<60, "Adult", "Senior"))) -> Young Adult | M4: =G4+H4+1 -> 1 | N4: =IF(M4=1,"Alone",IF(M4<=4,"Small Family","Large Family")) -> Alone | O4: =IF(J4<25, "Low Fare", IF(J4<=100, "Medium Fare", "High Fare")) -> Low Fare | P4: =IF(C4=1, "First Class", IF(C4=2, "Second Class", "Third Class")) -> Third Class | Q4: =IF(E4="male", 1, 2) -> 2
A5: 4 | B5: 1 | C5: 1 | D5: Futrelle, Mrs. Jacques Heath (Lily May Peel) | E5: female | F5: 35 | G5: 1 | H5: 0 | I5: 113803 | J5: 53.1 | K5: =IF(B5=1, "Survived", "Died") -> Survived | L5: =IF(F5<18, "Child", IF(F5<35, "Young Adult", IF(F5<60, "Adult", "Senior"))) -> Adult | M5: =G5+H5+1 -> 2 | N5: =IF(M5=1,"Alone",IF(M5<=4,"Small Family","Large Family")) -> Small Family | O5: =IF(J5<25, "Low Fare", IF(J5<=100, "Medium Fare", "High Fare")) -> Medium Fare | P5: =IF(C5=1, "First Class", IF(C5=2, "Second Class", "Third Class")) -> First Class | Q5: =IF(E5="male", 1, 2) -> 2
A6: 5 | B6: 0 | C6: 3 | D6: Allen, Mr. William Henry | E6: male | F6: 35 | G6: 0 | H6: 0 | I6: 373450 | J6: 8.05 | K6: =IF(B6=1, "Survived", "Died") -> Died | L6: =IF(F6<18, "Child", IF(F6<35, "Young Adult", IF(F6<60, "Adult", "Senior"))) -> Adult | M6: =G6+H6+1 -> 1 | N6: =IF(M6=1,"Alone",IF(M6<=4,"Small Family","Large Family")) -> Alone | O6: =IF(J6<25, "Low Fare", IF(J6<=100, "Medium Fare", "High Fare")) -> Low Fare | P6: =IF(C6=1, "First Class", IF(C6=2, "Second Class", "Third Class")) -> Third Class | Q6: =IF(E6="male", 1, 2) -> 1
A7: 6 | B7: 0 | C7: 3 | D7: Moran, Mr. James | E7: male | F7: 26 | G7: 0 | H7: 0 | I7: 330877 | J7: 8.4583 | K7: =IF(B7=1, "Survived", "Died") -> Died | L7: =IF(F7<18, "Child", IF(F7<35, "Young Adult", IF(F7<60, "Adult", "Senior"))) -> Young Adult | M7: =G7+H7+1 -> 1 | N7: =IF(M7=1,"Alone",IF(M7<=4,"Small Family","Large Family")) -> Alone | O7: =IF(J7<25, "Low Fare", IF(J7<=100, "Medium Fare", "High Fare")) -> Low Fare | P7: =IF(C7=1, "First Class", IF(C7=2, "Second Class", "Third Class")) -> Third Class | Q7: =IF(E7="male", 1, 2) -> 1
A8: 7 | B8: 0 | C8: 1 | D8: McCarthy, Mr. Timothy J | E8: male | F8: 54 | G8: 0 | H8: 0 | I8: 17463 | J8: 51.8625 | K8: =IF(B8=1, "Survived", "Died") -> Died | L8: =IF(F8<18, "Child", IF(F8<35, "Young Adult", IF(F8<60, "Adult", "Senior"))) -> Adult | M8: =G8+H8+1 -> 1 | N8: =IF(M8=1,"Alone",IF(M8<=4,"Small Family","Large Family")) -> Alone | O8: =IF(J8<25, "Low Fare", IF(J8<=100, "Medium Fare", "High Fare")) -> Medium Fare | P8: =IF(C8=1, "First Class", IF(C8=2, "Second Class", "Third Class")) -> First Class | Q8: =IF(E8="male", 1, 2) -> 1
A9: 8 | B9: 0 | C9: 3 | D9: Palsson, Master. Gosta Leonard | E9: male | F9: 2 | G9: 3 | H9: 1 | I9: 349909 | J9: 21.075 | K9: =IF(B9=1, "Survived", "Died") -> Died | L9: =IF(F9<18, "Child", IF(F9<35, "Young Adult", IF(F9<60, "Adult", "Senior"))) -> Child | M9: =G9+H9+1 -> 5 | N9: =IF(M9=1,"Alone",IF(M9<=4,"Small Family","Large Family")) -> Large Family | O9: =IF(J9<25, "Low Fare", IF(J9<=100, "Medium Fare", "High Fare")) -> Low Fare | P9: =IF(C9=1, "First Class", IF(C9=2, "Second Class", "Third Class")) -> Third Class | Q9: =IF(E9="male", 1, 2) -> 1
A10: 9 | B10: 1 | C10: 3 | D10: Johnson, Mrs. Oscar W (Elisabeth Vilhelmina Berg) | E10: female | F10: 27 | G10: 0 | H10: 2 | I10: 347742 | J10: 11.1333 | K10: =IF(B10=1, "Survived", "Died") -> Survived | L10: =IF(F10<18, "Child", IF(F10<35, "Young Adult", IF(F10<60, "Adult", "Senior"))) -> Young Adult | M10: =G10+H10+1 -> 3 | N10: =IF(M10=1,"Alone",IF(M10<=4,"Small Family","Large Family")) -> Small Family | O10: =IF(J10<25, "Low Fare", IF(J10<=100, "Medium Fare", "High Fare")) -> Low Fare | P10: =IF(C10=1, "First Class", IF(C10=2, "Second Class", "Third Class")) -> Third Class | Q10: =IF(E10="male", 1, 2) -> 2
A11: 10 | B11: 1 | C11: 2 | D11: Nasser, Mrs. Nicholas (Adele Achem) | E11: female | F11: 14 | G11: 1 | H11: 0 | I11: 237736 | J11: 30.0708 | K11: =IF(B11=1, "Survived", "Died") -> Survived | L11: =IF(F11<18, "Child", IF(F11<35, "Young Adult", IF(F11<60, "Adult", "Senior"))) -> Child | M11: =G11+H11+1 -> 2 | N11: =IF(M11=1,"Alone",IF(M11<=4,"Small Family","Large Family")) -> Small Family | O11: =IF(J11<25, "Low Fare", IF(J11<=100, "Medium Fare", "High Fare")) -> Medium Fare | P11: =IF(C11=1, "First Class", IF(C11=2, "Second Class", "Third Class")) -> Second Class | Q11: =IF(E11="male", 1, 2) -> 2
A12: 11 | B12: 1 | C12: 3 | D12: Sandstrom, Miss. Marguerite Rut | E12: female | F12: 4 | G12: 1 | H12: 1 | I12: PP 9549 | J12: 16.7 | K12: =IF(B12=1, "Survived", "Died") -> Survived | L12: =IF(F12<18, "Child", IF(F12<35, "Young Adult", IF(F12<60, "Adult", "Senior"))) -> Child | M12: =G12+H12+1 -> 3 | N12: =IF(M12=1,"Alone",IF(M12<=4,"Small Family","Large Family")) -> Small Family | O12: =IF(J12<25, "Low Fare", IF(J12<=100, "Medium Fare", "High Fare")) -> Low Fare | P12: =IF(C12=1, "First Class", IF(C12=2, "Second Class", "Third Class")) -> Third Class | Q12: =IF(E12="male", 1, 2) -> 2
A13: 12 | B13: 1 | C13: 1 | D13: Bonnell, Miss. Elizabeth | E13: female | F13: 58 | G13: 0 | H13: 0 | I13: 113783 | J13: 26.55 | K13: =IF(B13=1, "Survived", "Died") -> Survived | L13: =IF(F13<18, "Child", IF(F13<35, "Young Adult", IF(F13<60, "Adult", "Senior"))) -> Adult | M13: =G13+H13+1 -> 1 | N13: =IF(M13=1,"Alone",IF(M13<=4,"Small Family","Large Family")) -> Alone | O13: =IF(J13<25, "Low Fare", IF(J13<=100, "Medium Fare", "High Fare")) -> Medium Fare | P13: =IF(C13=1, "First Class", IF(C13=2, "Second Class", "Third Class")) -> First Class | Q13: =IF(E13="male", 1, 2) -> 2
... A892: 891 | B892: 0 | C892: 3 | D892: Dooley, Mr. Patrick | E892: male | F892: 32 | G892: 0 | H892: 0 | I892: 370376 | J892: 7.75 | K892: =IF(B892=1, "Survived", "Died") -> Died | L892: =IF(F892<18, "Child", IF(F892<35, "Young Adult", IF(F892<60, "Adult", "Senior"))) -> Young Adult | M892: =G892+H892+1 -> 1 | N892: =IF(M892=1,"Alone",IF(M892<=4,"Small Family","Large Family")) -> Alone | O892: =IF(J892<25, "Low Fare", IF(J892<=100, "Medium Fare", "High Fare")) -> Low Fare | P892: =IF(C892=1, "First Class", IF(C892=2, "Second Class", "Third Class")) -> Third Class | Q892: =IF(E892="male", 1, 2) -> 1

Sheet Statistics
A1: Section A. Dataset Statistics | D1: Section B. Descriptive Statistics
A2: KPI | B2: Formula | D2: Statistic | E2: Age | F2: Fare
A3: Total Passengers | B3: =COUNTA(CleanedData!A2:A892) -> 891 | D3: Mean | E3: =AVERAGE(CleanedData!F:F) -> 28.964276 | F3: =AVERAGE(CleanedData!J:J) -> 32.204208
A4: Survivors | B4: =COUNTIF(CleanedData!B:B,1) -> 342 | D4: Median | E4: =MEDIAN(CleanedData!F:F) -> 26 | F4: =MEDIAN(CleanedData!J:J) -> 14.4542
A5: Deaths | B5: =COUNTIF(CleanedData!B:B,0) -> 549 | D5: Minimum | E5: =MIN(CleanedData!F:F) -> 0.42 | F5: =MIN(CleanedData!J:J) -> 0
A6: Survival Rate | B6: =B4/B3 -> 0.38383838 | D6: Maximum | E6: =MAX(CleanedData!F:F) -> 80 | F6: =MAX(CleanedData!J:J) -> 512.3292
A7: Average Age | B7: =AVERAGE(CleanedData!F:F) -> 28.964276 | D7: Standard Deviation | E7: =_xlfn.STDEV.S(CleanedData!F:F) -> 13.085607 | F7: =_xlfn.STDEV.S(CleanedData!J:J) -> 49.693429
A8: Average Fare | B8: =AVERAGE(CleanedData!J:J) -> 32.204208
A9: Average Family Size | B9: =AVERAGE(CleanedData!M:M) -> 1.9046016
A10: Male Passengers | B10: =COUNTIF(CleanedData!Q:Q,1) -> 577
A11: Female Passengers | B11: =COUNTIF(CleanedData!Q:Q,2) -> 314

Sheet PivotTables
A3: Survival Status | B3: Passengers
A4: Died | B4: 549
A5: Survived | B5: 342
A6: Grand Total | B6: 891
A9: Passengers | B9: Survival Status
A10: Sex | B10: Died | C10: Survived | D10: Grand Total
A11: female | B11: 81 | C11: 233 | D11: 314
A12: male | B12: 468 | C12: 109 | D12: 577
A13: Grand Total | B13: 549 | C13: 342 | D13: 891
A16: Passengers | B16: Survival Status
A17: Passenger Class | B17: Died | C17: Survived | D17: Grand Total
A18: First Class | B18: 80 | C18: 136 | D18: 216
A19: Second Class | B19: 97 | C19: 87 | D19: 184
A20: Third Class | B20: 372 | C20: 119 | D20: 491
A21: Grand Total | B21: 549 | C21: 342 | D21: 891
A24: Passengers | B24: Survival Status
A25: Age Group | B25: Died | C25: Survived | D25: Grand Total
A26: Adult | B26: 122 | C26: 87 | D26: 209
A27: Child | B27: 52 | C27: 61 | D27: 113
A28: Senior | B28: 19 | C28: 7 | D28: 26
A29: Young Adult | B29: 356 | C29: 187 | D29: 543
A30: Grand Total | B30: 549 | C30: 342 | D30: 891
A33: Passengers | B33: Survival Status
A34: Family Group | B34: Died | C34: Survived | D34: Grand Total
A35: Alone | B35: 374 | C35: 163 | D35: 537
A36: Large Family | B36: 52 | C36: 10 | D36: 62
A37: Small Family | B37: 123 | C37: 169 | D37: 292
A38: Grand Total | B38: 549 | C38: 342 | D38: 891
A41: Passengers | B41: Survival Status
A42: Fare Category | B42: Died | C42: Survived | D42: Grand Total
A43: High Fare | B43: 14 | C43: 39 | D43: 53
A44: Low Fare | B44: 397 | C44: 160 | D44: 557
A45: Medium Fare | B45: 138 | C45: 143 | D45: 281
A46: Grand Total | B46: 549 | C46: 342 | D46: 891

Sheet Dashboard
B1: Titanic Survival Analysis Dashboard
B3: =Statistics!B3 -> 891 | E3: =Statistics!B4 -> 342 | H3: =Statistics!B5 -> 549 | K3: =Statistics!B6 -> 0.38383838 | N3: =Statistics!B7 -> 28.964276 | Q3: =Statistics!B8 -> 32.204208
B6: Total Passengers | E6: Survivors | H6: Deaths | K6: Survival Rate | N6: Average Age | Q6: Average Fare
